<sdf version='1.7'>
  <world name='default'>
    <light name='sun' type='directional'>
      <cast_shadows>1</cast_shadows>
      <pose>0 0 10 0 -0 0</pose>
      <diffuse>0.8 0.8 0.8 1</diffuse>
      <specular>0.2 0.2 0.2 1</specular>
      <attenuation>
        <range>1000</range>
        <constant>0.9</constant>
        <linear>0.01</linear>
        <quadratic>0.001</quadratic>
      </attenuation>
      <direction>-0.5 0.1 -0.9</direction>
      <spot>
        <inner_angle>0</inner_angle>
        <outer_angle>0</outer_angle>
        <falloff>0</falloff>
      </spot>
    </light>
    <model name='ground_plane'>
      <static>1</static>
      <link name='link'>
        <collision name='collision'>
          <geometry>
            <plane>
              <normal>0 0 1</normal>
              <size>100 100</size>
            </plane>
          </geometry>
          <surface>
            <contact>
              <collide_bitmask>65535</collide_bitmask>
              <ode/>
            </contact>
            <friction>
              <ode>
                <mu>100</mu>
                <mu2>50</mu2>
              </ode>
              <torsional>
                <ode/>
              </torsional>
            </friction>
            <bounce/>
          </surface>
          <max_contacts>10</max_contacts>
        </collision>
        <visual name='visual'>
          <cast_shadows>0</cast_shadows>
          <geometry>
            <plane>
              <normal>0 0 1</normal>
              <size>100 100</size>
            </plane>
          </geometry>
          <material>
            <script>
              <uri>file://media/materials/scripts/gazebo.material</uri>
              <name>Gazebo/Grey</name>
            </script>
          </material>
        </visual>
        <self_collide>0</self_collide>
        <enable_wind>0</enable_wind>
        <kinematic>0</kinematic>
      </link>
    </model>
    <scene>
      <ambient>0.63 0.63 0.63 1</ambient>
      <background>0.6666 0.6471 0.6078 1</background>
      <grid>1</grid>
      <shadows>0</shadows>
    </scene>
    <light name='some_light' type='directional'>
      <diffuse>0.7 0.7 0.7 0</diffuse>
      <specular>1 1 1 0</specular>
      <direction>-1 -1 -1</direction>
      <attenuation>
        <range>10</range>
      </attenuation>
      <spot>
        <inner_angle>0</inner_angle>
        <outer_angle>0</outer_angle>
        <falloff>0</falloff>
      </spot>
    </light>
    <gravity>0 0 -9.8</gravity>
    <magnetic_field>6e-06 2.3e-05 -4.2e-05</magnetic_field>
    <atmosphere type='adiabatic'/>
    <physics type='ode'>
      <max_step_size>0.001</max_step_size>
      <real_time_factor>1</real_time_factor>
      <real_time_update_rate>1000</real_time_update_rate>
    </physics>
    <wind/>
    <spherical_coordinates>
      <surface_model>EARTH_WGS84</surface_model>
      <latitude_deg>0</latitude_deg>
      <longitude_deg>0</longitude_deg>
      <elevation>0</elevation>
      <heading_deg>0</heading_deg>
    </spherical_coordinates>
    <model name='tm5-700'>
      <joint name='world_joint' type='fixed'>
        <pose relative_to='__model__'>0 0 0 0 -0 0</pose>
        <parent>world</parent>
        <child>base</child>
      </joint>
      <link name='base'>
        <pose relative_to='world_joint'>0 0 0 0 -0 0</pose>
        <inertial>
          <pose>0 0 0 0 -0 0</pose>
          <mass>1</mass>
          <inertia>
            <ixx>0.00110833</ixx>
            <ixy>0</ixy>
            <ixz>0</ixz>
            <iyy>0.00110833</iyy>
            <iyz>0</iyz>
            <izz>0.0018</izz>
          </inertia>
        </inertial>
        <collision name='base_fixed_joint_lump__link_0_collision'>
          <pose>0 0 0 0 -0 0</pose>
          <geometry>
            <mesh>
              <scale>1 1 1</scale>
              <uri>/home/strangelove/catkin_ws/src/tmr_ros1/tm_description/meshes/tm5-900/collision/tm5-base_c.stl</uri>
            </mesh>
          </geometry>
          <surface>
            <contact>
              <ode/>
            </contact>
            <friction>
              <ode/>
              <torsional>
                <ode/>
              </torsional>
            </friction>
            <bounce/>
          </surface>
          <max_contacts>10</max_contacts>
        </collision>
        <visual name='base_fixed_joint_lump__link_0_visual'>
          <pose>0 0 0 0 -0 0</pose>
          <geometry>
            <mesh>
              <scale>1 1 1</scale>
              <uri>/home/strangelove/catkin_ws/src/tmr_ros1/tm_description/meshes/tm5-900/visual/tm5-base.obj</uri>
            </mesh>
          </geometry>
          <material>
            <script>
              <name>Gazebo/Grey</name>
              <uri>file://media/materials/scripts/gazebo.material</uri>
            </script>
          </material>
        </visual>
        <self_collide>1</self_collide>
        <enable_wind>0</enable_wind>
        <kinematic>0</kinematic>
      </link>
      <joint name='shoulder_1_joint' type='revolute'>
        <pose relative_to='base'>0 0 0.1452 0 -0 0</pose>
        <parent>base</parent>
        <child>link_1</child>
        <axis>
          <xyz>0 0 1</xyz>
          <limit>
            <lower>-4.71239</lower>
            <upper>4.71239</upper>
            <effort>157</effort>
            <velocity>3.14159</velocity>
          </limit>
          <dynamics>
            <damping>0</damping>
            <friction>0</friction>
            <spring_reference>0</spring_reference>
            <spring_stiffness>0</spring_stiffness>
          </dynamics>
        </axis>
      </joint>
      <link name='link_1'>
        <pose relative_to='shoulder_1_joint'>0 0 0 0 -0 0</pose>
        <inertial>
          <pose>0 0 0 0 -0 0</pose>
          <mass>4.032</mass>
          <inertia>
            <ixx>0.00880012</ixx>
            <ixy>0</ixy>
            <ixz>0</ixz>
            <iyy>0.011549</iyy>
            <iyz>0</iyz>
            <izz>0.0119701</izz>
          </inertia>
        </inertial>
        <collision name='link_1_collision'>
          <pose>0 0 0 0 -0 0</pose>
          <geometry>
            <mesh>
              <scale>1 1 1</scale>
              <uri>/home/strangelove/catkin_ws/src/tmr_ros1/tm_description/meshes/tm5-900/collision/tmr_400w_01_c.stl</uri>
            </mesh>
          </geometry>
          <surface>
            <contact>
              <ode/>
            </contact>
            <friction>
              <ode/>
              <torsional>
                <ode/>
              </torsional>
            </friction>
            <bounce/>
          </surface>
          <max_contacts>10</max_contacts>
        </collision>
        <visual name='link_1_visual'>
          <pose>0 0 0 0 -0 0</pose>
          <geometry>
            <mesh>
              <scale>1 1 1</scale>
              <uri>/home/strangelove/catkin_ws/src/tmr_ros1/tm_description/meshes/tm5-900/visual/tmr_400w_01.obj</uri>
            </mesh>
          </geometry>
          <material>
            <script>
              <name>Gazebo/Motorway</name>
              <uri>file://media/materials/scripts/gazebo.material</uri>
            </script>
          </material>
        </visual>
        <self_collide>1</self_collide>
        <enable_wind>0</enable_wind>
        <kinematic>0</kinematic>
      </link>
      <joint name='shoulder_2_joint' type='revolute'>
        <pose relative_to='link_1'>0 0 0 1.57079 -1.57079 3.14159</pose>
        <parent>link_1</parent>
        <child>link_2</child>
        <axis>
          <xyz>0 0 1</xyz>
          <limit>
            <lower>-3.14159</lower>
            <upper>3.14159</upper>
            <effort>157</effort>
            <velocity>3.14159</velocity>
          </limit>
          <dynamics>
            <damping>0</damping>
            <friction>0</friction>
            <spring_reference>0</spring_reference>
            <spring_stiffness>0</spring_stiffness>
          </dynamics>
        </axis>
      </joint>
      <link name='link_2'>
        <pose relative_to='shoulder_2_joint'>0 0 0 0 -0 0</pose>
        <inertial>
          <pose>0 0 0 0 -0 0</pose>
          <mass>8.567</mass>
          <inertia>
            <ixx>0.0235521</ixx>
            <ixy>0</ixy>
            <ixz>0</ixz>
            <iyy>0.198252</iyy>
            <iyz>0</iyz>
            <izz>0.204593</izz>
          </inertia>
        </inertial>
        <collision name='link_2_collision'>
          <pose>0 0 0 0 -0 0</pose>
          <geometry>
            <mesh>
              <scale>1 1 1</scale>
              <uri>/home/strangelove/catkin_ws/src/tmr_ros1/tm_description/meshes/tm5-700/collision/tm5-700_arm1_c.stl</uri>
            </mesh>
          </geometry>
          <surface>
            <contact>
              <ode/>
            </contact>
            <friction>
              <ode/>
              <torsional>
                <ode/>
              </torsional>
            </friction>
            <bounce/>
          </surface>
          <max_contacts>10</max_contacts>
        </collision>
        <visual name='link_2_visual'>
          <pose>0 0 0 0 -0 0</pose>
          <geometry>
            <mesh>
              <scale>1 1 1</scale>
              <uri>/home/strangelove/catkin_ws/src/tmr_ros1/tm_description/meshes/tm5-700/visual/tm5-700_arm1.obj</uri>
            </mesh>
          </geometry>
          <material>
            <script>
              <name>Gazebo/Motorway</name>
              <uri>file://media/materials/scripts/gazebo.material</uri>
            </script>
          </material>
        </visual>
        <self_collide>1</self_collide>
        <enable_wind>0</enable_wind>
        <kinematic>0</kinematic>
      </link>
      <joint name='elbow_joint' type='revolute'>
        <pose relative_to='link_2'>0.329 0 0 0 -0 0</pose>
        <parent>link_2</parent>
        <child>link_3</child>
        <axis>
          <xyz>0 0 1</xyz>
          <limit>
            <lower>-2.70526</lower>
            <upper>2.70526</upper>
            <effort>157</effort>
            <velocity>3.14159</velocity>
          </limit>
          <dynamics>
            <damping>0</damping>
            <friction>0</friction>
            <spring_reference>0</spring_reference>
            <spring_stiffness>0</spring_stiffness>
          </dynamics>
        </axis>
      </joint>
      <link name='link_3'>
        <pose relative_to='elbow_joint'>0 0 0 0 -0 0</pose>
        <inertial>
          <pose>0 0 0 0 -0 0</pose>
          <mass>2.273</mass>
          <inertia>
            <ixx>0.00338018</ixx>
            <ixy>0</ixy>
            <ixz>0</ixz>
            <iyy>0.0338291</iyy>
            <iyz>0</iyz>
            <izz>0.0343282</izz>
          </inertia>
        </inertial>
        <collision name='link_3_collision'>
          <pose>0 0 0 0 -0 0</pose>
          <geometry>
            <mesh>
              <scale>1 1 1</scale>
              <uri>/home/strangelove/catkin_ws/src/tmr_ros1/tm_description/meshes/tm5-700/collision/tm5-700_arm2_c.stl</uri>
            </mesh>
          </geometry>
          <surface>
            <contact>
              <ode/>
            </contact>
            <friction>
              <ode/>
              <torsional>
                <ode/>
              </torsional>
            </friction>
            <bounce/>
          </surface>
          <max_contacts>10</max_contacts>
        </collision>
        <visual name='link_3_visual'>
          <pose>0 0 0 0 -0 0</pose>
          <geometry>
            <mesh>
              <scale>1 1 1</scale>
              <uri>/home/strangelove/catkin_ws/src/tmr_ros1/tm_description/meshes/tm5-700/visual/tm5-700_arm2.obj</uri>
            </mesh>
          </geometry>
          <material>
            <script>
              <name>Gazebo/Motorway</name>
              <uri>file://media/materials/scripts/gazebo.material</uri>
            </script>
          </material>
        </visual>
        <self_collide>1</self_collide>
        <enable_wind>0</enable_wind>
        <kinematic>0</kinematic>
      </link>
      <joint name='wrist_1_joint' type='revolute'>
        <pose relative_to='link_3'>0.3115 0 -0.1223 0 -0 1.5708</pose>
        <parent>link_3</parent>
        <child>link_4</child>
        <axis>
          <xyz>0 0 1</xyz>
          <limit>
            <lower>-3.14159</lower>
            <upper>3.14159</upper>
            <effort>43</effort>
            <velocity>3.92699</velocity>
          </limit>
          <dynamics>
            <damping>0</damping>
            <friction>0</friction>
            <spring_reference>0</spring_reference>
            <spring_stiffness>0</spring_stiffness>
          </dynamics>
        </axis>
      </joint>
      <link name='link_4'>
        <pose relative_to='wrist_1_joint'>0 0 0 0 -0 0</pose>
        <inertial>
          <pose>0 0 0 0 -0 0</pose>
          <mass>1.576</mass>
          <inertia>
            <ixx>0.00205841</ixx>
            <ixy>0</ixy>
            <ixz>0</ixz>
            <iyy>0.00256308</iyy>
            <iyz>0</iyz>
            <izz>0.00264321</izz>
          </inertia>
        </inertial>
        <collision name='link_4_collision'>
          <pose>0 0 0 0 -0 0</pose>
          <geometry>
            <mesh>
              <scale>1 1 1</scale>
              <uri>/home/strangelove/catkin_ws/src/tmr_ros1/tm_description/meshes/tm5-900/collision/tmr_100w_01_c.stl</uri>
            </mesh>
          </geometry>
          <surface>
            <contact>
              <ode/>
            </contact>
            <friction>
              <ode/>
              <torsional>
                <ode/>
              </torsional>
            </friction>
            <bounce/>
          </surface>
          <max_contacts>10</max_contacts>
        </collision>
        <visual name='link_4_visual'>
          <pose>0 0 0 0 -0 0</pose>
          <geometry>
            <mesh>
              <scale>1 1 1</scale>
              <uri>/home/strangelove/catkin_ws/src/tmr_ros1/tm_description/meshes/tm5-900/visual/tmr_100w_01.obj</uri>
            </mesh>
          </geometry>
          <material>
            <script>
              <name>Gazebo/Motorway</name>
              <uri>file://media/materials/scripts/gazebo.material</uri>
            </script>
          </material>
        </visual>
        <self_collide>1</self_collide>
        <enable_wind>0</enable_wind>
        <kinematic>0</kinematic>
      </link>
      <joint name='wrist_2_joint' type='revolute'>
        <pose relative_to='link_4'>0 -0.106 0 1.5708 -0 0</pose>
        <parent>link_4</parent>
        <child>link_5</child>
        <axis>
          <xyz>0 0 1</xyz>
          <limit>
            <lower>-3.14159</lower>
            <upper>3.14159</upper>
            <effort>43</effort>
            <velocity>3.92699</velocity>
          </limit>
          <dynamics>
            <damping>0</damping>
            <friction>0</friction>
            <spring_reference>0</spring_reference>
            <spring_stiffness>0</spring_stiffness>
          </dynamics>
        </axis>
      </joint>
      <link name='link_5'>
        <pose relative_to='wrist_2_joint'>0 0 0 0 -0 0</pose>
        <inertial>
          <pose>0 0 0 0 -0 0</pose>
          <mass>1.576</mass>
          <inertia>
            <ixx>0.00205841</ixx>
            <ixy>0</ixy>
            <ixz>0</ixz>
            <iyy>0.00256308</iyy>
            <iyz>0</iyz>
            <izz>0.00264321</izz>
          </inertia>
        </inertial>
        <collision name='link_5_collision'>
          <pose>0 0 0 0 -0 0</pose>
          <geometry>
            <mesh>
              <scale>1 1 1</scale>
              <uri>/home/strangelove/catkin_ws/src/tmr_ros1/tm_description/meshes/tm5-900/collision/tmr_100w_02_c.stl</uri>
            </mesh>
          </geometry>
          <surface>
            <contact>
              <ode/>
            </contact>
            <friction>
              <ode/>
              <torsional>
                <ode/>
              </torsional>
            </friction>
            <bounce/>
          </surface>
          <max_contacts>10</max_contacts>
        </collision>
        <visual name='link_5_visual'>
          <pose>0 0 0 0 -0 0</pose>
          <geometry>
            <mesh>
              <scale>1 1 1</scale>
              <uri>/home/strangelove/catkin_ws/src/tmr_ros1/tm_description/meshes/tm5-900/visual/tmr_100w_02.obj</uri>
            </mesh>
          </geometry>
          <material>
            <script>
              <name>Gazebo/Motorway</name>
              <uri>file://media/materials/scripts/gazebo.material</uri>
            </script>
          </material>
        </visual>
        <self_collide>1</self_collide>
        <enable_wind>0</enable_wind>
        <kinematic>0</kinematic>
      </link>
      <joint name='wrist_3_joint' type='revolute'>
        <pose relative_to='link_5'>0 -0.11315 0 1.5708 -0 0</pose>
        <parent>link_5</parent>
        <child>link_6</child>
        <axis>
          <xyz>0 0 1</xyz>
          <limit>
            <lower>-4.71239</lower>
            <upper>4.71239</upper>
            <effort>43</effort>
            <velocity>3.92699</velocity>
          </limit>
          <dynamics>
            <damping>0</damping>
            <friction>0</friction>
            <spring_reference>0</spring_reference>
            <spring_stiffness>0</spring_stiffness>
          </dynamics>
        </axis>
      </joint>
      <link name='link_6'>
        <pose relative_to='wrist_3_joint'>0 0 0 0 -0 0</pose>
        <inertial>
          <pose>0 0 0 0 -0 0</pose>
          <mass>0.65</mass>
          <inertia>
            <ixx>0.000774544</ixx>
            <ixy>0</ixy>
            <ixz>0</ixz>
            <iyy>0.00138381</iyy>
            <iyz>0</iyz>
            <izz>0.0015595</izz>
          </inertia>
        </inertial>
        <collision name='link_6_collision'>
          <pose>0 0 0 0 -0 0</pose>
          <geometry>
            <mesh>
              <scale>1 1 1</scale>
              <uri>/home/strangelove/catkin_ws/src/tmr_ros1/tm_description/meshes/tm5-900/collision/tmr_ee_c.stl</uri>
            </mesh>
          </geometry>
          <surface>
            <contact>
              <ode/>
            </contact>
            <friction>
              <ode/>
              <torsional>
                <ode/>
              </torsional>
            </friction>
            <bounce/>
          </surface>
          <max_contacts>10</max_contacts>
        </collision>
        <visual name='link_6_visual'>
          <pose>0 0 0 0 -0 0</pose>
          <geometry>
            <mesh>
              <scale>1 1 1</scale>
              <uri>/home/strangelove/catkin_ws/src/tmr_ros1/tm_description/meshes/tm5-900/visual/tmr_ee.obj</uri>
            </mesh>
          </geometry>
          <material>
            <script>
              <name>Gazebo/Grey</name>
              <uri>file://media/materials/scripts/gazebo.material</uri>
            </script>
          </material>
        </visual>
        <self_collide>1</self_collide>
        <enable_wind>0</enable_wind>
        <kinematic>0</kinematic>
      </link>
      <static>0</static>
      <plugin name='gazebo_ros_control' filename='libgazebo_ros_control.so'>
        <robotNamespace>/</robotNamespace>
        <robotSimType>gazebo_ros_control/DefaultRobotHWSim</robotSimType>
      </plugin>
      <pose>0 0 0 0 -0 0</pose>
    </model>
    <model name='ender3bed'>
      <static>1</static>
      <link name='link'>
        <collision name='collision'>
          <pose>0 0 0 0 0 -1.5708</pose>
          <geometry>
            <mesh>
              <scale>1 1 1</scale>
              <uri>model://printbed/meshes/moddedprintbed.stl</uri>
            </mesh>
          </geometry>
          <max_contacts>10</max_contacts>
          <surface>
            <contact>
              <ode/>
            </contact>
            <bounce/>
            <friction>
              <torsional>
                <ode/>
              </torsional>
              <ode/>
            </friction>
          </surface>
        </collision>
        <visual name='visual'>
          <pose>0 0 0 0 0 -1.5708</pose>
          <geometry>
            <mesh>
              <scale>1 1 1</scale>
              <uri>model://printbed/meshes/moddedprintbed.stl</uri>
            </mesh>
          </geometry>
          <material>
            <ambient>0 0 0 1</ambient>
            <diffuse>0 0 0 1</diffuse>
          </material>
        </visual>
        <self_collide>0</self_collide>
        <enable_wind>0</enable_wind>
        <kinematic>0</kinematic>
      </link>
      <pose>-0.00838 -0.874198 0 0 -0 0</pose>
    </model>
    <model name='ender3Model'>
      <link name='base_link'>
        <visual name='base_visual'>
          <geometry>
            <mesh>
              <uri>model://printer/meshes/ender3.stl</uri>
              <scale>1 1 1</scale>
            </mesh>
          </geometry>
        </visual>
        <collision name='base_collision'>
          <geometry>
            <mesh>
              <uri>model://printer/meshes/ender3.stl</uri>
            </mesh>
          </geometry>
          <max_contacts>10</max_contacts>
          <surface>
            <contact>
              <ode/>
            </contact>
            <bounce/>
            <friction>
              <torsional>
                <ode/>
              </torsional>
              <ode/>
            </friction>
          </surface>
        </collision>
        <self_collide>0</self_collide>
        <inertial>
          <pose>0 0 0 0 -0 0</pose>
          <inertia>
            <ixx>1</ixx>
            <ixy>0</ixy>
            <ixz>0</ixz>
            <iyy>1</iyy>
            <iyz>0</iyz>
            <izz>1</izz>
          </inertia>
          <mass>1</mass>
        </inertial>
        <enable_wind>0</enable_wind>
        <kinematic>0</kinematic>
      </link>
      <pose>1.47457 0.21824 0 0 -0 0</pose>
    </model>
    <model name='TVStand'>
      <static>1</static>
      <link name='body'>
        <pose>0 0 0 0 -0 0</pose>
        <visual name='visual'>
          <geometry>
            <mesh>
              <uri>https://fuel.gazebosim.org/1.0/openrobotics/models/tvstand/2/files/meshes/TVStand.obj</uri>
            </mesh>
          </geometry>
        </visual>
        <collision name='collision'>
          <geometry>
            <mesh>
              <uri>https://fuel.gazebosim.org/1.0/openrobotics/models/tvstand/2/files/meshes/TVStand_Col.obj</uri>
            </mesh>
          </geometry>
          <max_contacts>10</max_contacts>
          <surface>
            <contact>
              <ode/>
            </contact>
            <bounce/>
            <friction>
              <torsional>
                <ode/>
              </torsional>
              <ode/>
            </friction>
          </surface>
        </collision>
        <self_collide>0</self_collide>
        <enable_wind>0</enable_wind>
        <kinematic>0</kinematic>
      </link>
      <pose>1.58476 0.384749 0 0 -0 0</pose>
    </model>
    <state world_name='default'>
      <sim_time>24 726000000</sim_time>
      <real_time>116 136687810</real_time>
      <wall_time>1697899305 319677097</wall_time>
      <iterations>24726</iterations>
      <model name='TVStand'>
        <pose>0.75 0 0 0 0 -1.57</pose>
        <scale>1 1 1</scale>
        <link name='body'>
          <pose>0.75 0 0 0 0 -1.57</pose>
          <velocity>0 0 0 0 -0 0</velocity>
          <acceleration>0 0 0 0 -0 0</acceleration>
          <wrench>0 0 0 0 -0 0</wrench>
        </link>
      </model>
      <model name='ender3Model'>
        <pose>0.7 0 0.45 0 0 -1.57</pose>
        <scale>1 1 1</scale>
        <link name='base_link'>
          <pose>0.7 0 0.45 0 0 -1.57</pose>
          <velocity>0 0 0 0 -0 0</velocity>
          <acceleration>0 0 0 0 -0 0</acceleration>
          <wrench>0 0 0 0 -0 0</wrench>
        </link>
      </model>
      <model name='ender3bed'>
        <pose>0.57 0 0.558 0 -0 0</pose>
        <scale>1 1 1</scale>
        <link name='link'>
          <pose>0.57 0 0.558 0 -0 0</pose>
          <velocity>0 0 0 0 -0 0</velocity>
          <acceleration>0 0 0 0 -0 0</acceleration>
          <wrench>0 0 0 0 -0 0</wrench>
        </link>
      </model>
      <model name='ground_plane'>
        <pose>0 0 0 0 -0 0</pose>
        <scale>1 1 1</scale>
        <link name='link'>
          <pose>0 0 0 0 -0 0</pose>
          <velocity>0 0 0 0 -0 0</velocity>
          <acceleration>0 0 0 0 -0 0</acceleration>
          <wrench>0 0 0 0 -0 0</wrench>
        </link>
      </model>
      <model name='tm5-700'>
        <pose>0 0 0 0 -0 0</pose>
        <scale>1 1 1</scale>
        <link name='base'>
          <pose>0 0 0 0 -0 0</pose>
          <velocity>-0.000117 -2.5e-05 -8.2e-05 0.143035 -0.05292 -0.001338</velocity>
          <acceleration>-0.23987 0.033065 1.91778 -0.822988 -1.36069 0.091975</acceleration>
          <wrench>-0.23987 0.033065 1.91778 0 -0 0</wrench>
        </link>
        <link name='link_1'>
          <pose>-9.9e-05 -2.8e-05 0.145199 0.002549 -0.000747 -0.001299</pose>
          <velocity>-6.2e-05 -0.001528 0.000149 -0.267684 0.01172 0.046063</velocity>
          <acceleration>2.84329 -7.80913 2.16453 -1.89834 -1.36014 -2.3501</acceleration>
          <wrench>11.4642 -31.4864 8.72739 0 -0 0</wrench>
        </link>
        <link name='link_2'>
          <pose>-0.0001 -2.8e-05 0.145199 -1.38598 -1.55528 -0.186059</pose>
          <velocity>3.3e-05 -0.001304 0.000207 2.86399 -0.344812 -3.04672</velocity>
          <acceleration>3.06329 -7.39871 2.22781 1.16699 1.3739 -0.845953</acceleration>
          <wrench>26.2432 -63.3847 19.0857 0 -0 0</wrench>
        </link>
        <link name='link_3'>
          <pose>0.004902 -0.000976 0.474377 -1.38573 -1.55528 -0.18631</pose>
          <velocity>5.28489 0.090594 -0.039198 2.86345 -0.344197 -3.04671</velocity>
          <acceleration>-20.1972 1.61254 2.78574 -1.49156 0.899279 2.63071</acceleration>
          <wrench>-45.9082 3.66531 6.33199 0 -0 0</wrench>
        </link>
        <link name='link_4'>
          <pose>0.00949 -0.124182 0.785693 -1.56793 0.015215 -0.001154</pose>
          <velocity>10.294 0.178365 -0.039426 2.86198 -0.344551 -3.04617</velocity>
          <acceleration>-42.0039 10.2362 13.5914 -2.37082 -1.11101 -1.15614</acceleration>
          <wrench>-66.1982 16.1323 21.42 0 -0 0</wrench>
        </link>
        <link name='link_5'>
          <pose>0.011102 -0.1245 0.89175 0.003009 0.015253 -0.001022</pose>
          <velocity>11.9967 0.209197 -0.052063 2.84929 -0.344451 -3.03768</velocity>
          <acceleration>-49.5201 13.2794 13.9045 -0.546142 0.765106 2.40626</acceleration>
          <wrench>-78.0437 20.9283 21.9134 0 -0 0</wrench>
        </link>
        <link name='link_6'>
          <pose>0.010985 -0.237651 0.891408 1.57383 0.015233 -0.00097</pose>
          <velocity>12.0027 0.209187 -0.016711 2.84705 -0.344471 -3.0374</velocity>
          <acceleration>-49.1403 13.2468 23.2638 -0.577966 0.592617 2.89797</acceleration>
          <wrench>-31.9412 8.61045 15.1214 0 -0 0</wrench>
        </link>
      </model>
      <light name='some_light'>
        <pose>0 0 0 0 -0 0</pose>
      </light>
      <light name='sun'>
        <pose>0 0 10 0 -0 0</pose>
      </light>
    </state>
    <gui fullscreen='0'>
      <camera name='user_camera'>
        <pose>-0.781223 -1.87691 1.0531 0 0.167644 0.984183</pose>
        <view_controller>orbit</view_controller>
        <projection_type>perspective</projection_type>
      </camera>
    </gui>
  </world>
</sdf>
